<?xml version="1.0"?>
<robot name="diff_drive" xmlns:xacro="http://www.ros.org/wiki/xacro">

  <!-- Define materials -->
  <material name="orange">
    <color rgba="1 0.5 0 1"/>
  </material>
  <material name="black">
    <color rgba="0 0 0 1"/>
  </material>
  <material name="white">
    <color rgba="1 1 1 1"/>
  </material>
  <material name="grey">
    <color rgba="0.5 0.5 0.5 1"/>
  </material>

  <!-- Base Footprint -->
  <link name="base_footprint">
    <collision>
      <geometry>
        <box size="0.5 0.5 0.01"/> <!-- A small box for collision -->
      </geometry>
    </collision>

    <visual>
      <geometry>
        <box size="0.5 0.5 0.01"/>
      </geometry>
      <material name="grey"/>
    </visual>

    <inertial>
      <mass value="0.0"/> <!-- No mass, since it's just a frame -->
    </inertial>
  </link>

  <!-- Base Link -->
  <link name="base_link">
    <collision>
      <origin xyz="-0.151427 0 0.5" rpy="0 0 0"/>
      <geometry>
        <box size="2.01142 1 0.268726"/>
      </geometry>
    </collision>

    <visual>
      <origin xyz="-0.151427 0 0.5" rpy="0 0 0"/>
      <geometry>
        <box size="2.01142 1 0.268726"/>
      </geometry>
      <material name="orange"/>
    </visual>

    <inertial>
      <origin xyz="-0.151427 0 0.5" rpy="0 0 0"/>
      <mass value="1.14395"/>
      <inertia
        ixx="0.126164"
        ixy="0.0"
        ixz="0.0"
        iyy="0.416519"
        iyz="0.0"
        izz="0.481014"/>
    </inertial>
  </link>

  <!-- Fixed Joint between base_footprint and base_link -->
  <joint name="base_footprint_joint" type="fixed">
    <parent link="base_footprint"/>
    <child link="base_link"/>
    <origin xyz="0 0 0" rpy="0 0 0"/> <!-- Adjust if necessary -->
  </joint>

  <!-- Left Wheel Joint -->
  <joint name="left_wheel_joint" type="continuous">
    <origin xyz="0.554283 0.625029 0.4" rpy="-1.5707 0 0"/>
    <parent link="base_link"/>
    <child link="left_wheel"/>
    <axis xyz="0 0 1"/>
    <dynamics damping="0.2"/>
  </joint>

  <!-- Left Wheel Link -->
  <link name="left_wheel">
    <collision>
      <geometry>
        <sphere radius="0.2"/>
      </geometry>
    </collision>

    <visual>
      <geometry>
        <sphere radius="0.2"/>
      </geometry>
      <material name="black"/>
    </visual>

    <inertial>
      <mass value="2"/>
      <inertia ixx="0.145833"
               ixy="0.0"
               ixz="0.0"
               iyy="0.145833"
               iyz="0.0"
               izz="0.125"/>
    </inertial>
  </link>

  <!-- Right Wheel Joint -->
  <joint name="right_wheel_joint" type="continuous">
    <origin xyz="0.554283 -0.625029 0.4" rpy="-1.5707 0 0"/>
    <parent link="base_link"/>
    <child link="right_wheel"/>
    <axis xyz="0 0 1"/>
    <dynamics damping="0.2"/>
  </joint>

  <!-- Right Wheel Link -->
  <link name="right_wheel">
    <collision>
      <geometry>
        <sphere radius="0.2"/>
      </geometry>
    </collision>

    <visual>
      <geometry>
        <sphere radius="0.2"/>
      </geometry>
      <material name="black"/>
    </visual>

    <inertial>
      <mass value="2"/>
      <inertia ixx="0.145833"
               ixy="0.0"
               ixz="0.0"
               iyy="0.145833"
               iyz="0.0"
               izz="0.125"/>
    </inertial>
  </link>

  <!-- Caster Joint -->
  <joint name="caster_joint" type="fixed">
    <origin xyz="-0.957138 -0 0.3" rpy="0 0 0"/>
    <parent link="base_link"/>
    <child link="caster"/>
  </joint>

  <!-- Caster Link -->
  <link name="caster">
    <collision>
      <geometry>
        <sphere radius="0.1"/>
      </geometry>
    </collision>

    <visual>
      <geometry>
        <sphere radius="0.1"/>
      </geometry>
      <material name="white"/>
    </visual>

    <inertial>
      <mass value="0.005"/>
      <inertia
        ixx="0.1"
        ixy="0.0"
        ixz="0.0"
        iyy="0.1"
        iyz="0.0"
        izz="0.1"/>
    </inertial>
  </link>

  <!-- LIDAR Joint -->
  <joint name="lidar_joint" type="fixed">
    <origin xyz="0.2 0 0.73" rpy="0 0 0"/> <!-- Adjusted height to 0.75 -->
    <parent link="base_link"/>
    <child link="lidar_link"/>
  </joint>

  <!-- LIDAR Link -->
  <link name="lidar_link">
    <inertial>
      <mass value="0.114"/>
      <inertia
        ixx="0.001"
        ixy="0.000"
        ixz="0.000"
        iyy="0.001"
        iyz="0.000"
        izz="0.001"/>
    </inertial>

    <collision>
      <geometry>
        <cylinder radius="0.0508" length="0.18" />
      </geometry>
    </collision>

    <visual>
      <geometry>
        <cylinder radius="0.0508" length="0.18" />
      </geometry>
      <material name="black"/>
    </visual>
  </link>

  <!-- IMU Link -->
  <link name="imu">
    <inertial>
      <mass value="0.1"/>
      <inertia
        ixx="0.001"
        ixy="0.000"
        ixz="0.000"
        iyy="0.001"
        iyz="0.000"
        izz="0.001"/>
    </inertial>

    <collision>
      <geometry>
        <cylinder radius="0.05" length="0.1" />
      </geometry>
    </collision>

    <visual>
      <geometry>
        <cylinder radius="0.05" length="0.1" />
      </geometry>
      <material name="grey"/>
    </visual>
  </link>

  <!-- IMU Joint -->
  <joint name="imu_joint" type="fixed">
    <origin xyz="0 0 0.65" rpy="0 0 0"/>
    <parent link="base_link"/>
    <child link="imu"/>
  </joint>

  <ros2_control name="GazeboSystem" type="system">
    <hardware>
      <plugin>gazebo_ros2_control/GazeboSystem</plugin>
    </hardware>
    <joint name="left_wheel_joint">
      <command_interface name="velocity">
        <param name="min">-1</param>
        <param name="max">1</param>
      </command_interface>
      <state_interface name="position"/>
      <state_interface name="velocity"/>
    </joint>
    <joint name="right_wheel_joint">
      <command_interface name="velocity">
        <param name="min">-1</param>
        <param name="max">1</param>
      </command_interface>
      <state_interface name="position"/>
      <state_interface name="velocity"/>
    </joint>
  </ros2_control>

  <gazebo reference="lidar_link">
    <sensor name="lidar" type="ray">
      <origin xyz="0.215 0 0.215" rpy="0 0 0"/>
      <always_on>true</always_on>
      <visualize>true</visualize>
      <update_rate>5</update_rate>
      <ray>
        <scan>
          <horizontal>
            <samples>360</samples>
            <resolution>1.00000</resolution>
            <min_angle>0.000000</min_angle>
            <max_angle>6.280000</max_angle>
          </horizontal>
        </scan>
        <range>
          <min>0.120000</min>
          <max>100</max>
          <resolution>0.010000</resolution>
        </range>
        <noise>
          <type>gaussian</type>
          <mean>0.0</mean>
          <stddev>0.01</stddev>
        </noise>
      </ray>
      <plugin name="scan" filename="libgazebo_ros_ray_sensor.so">
        <ros>
          <remapping>~/out:=scan</remapping>
        </ros>
        <output_type>sensor_msgs/LaserScan</output_type>
        <frame_name>lidar_link</frame_name>
      </plugin>
    </sensor>
  </gazebo>

  <gazebo reference="imu">
    <sensor name="imu_sensor" type="imu">
      <always_on>true</always_on>
      <update_rate>100</update_rate>
      <imu>
        <angular_velocity>
          <x>
            <noise type="gaussian">
              <mean>0.0</mean>
              <stddev>2e-4</stddev>
              <bias_mean>0.0000075</bias_mean>
              <bias_stddev>0.0000008</bias_stddev>
            </noise>
          </x>
          <y>
            <noise type="gaussian">
              <mean>0.0</mean>
              <stddev>2e-4</stddev>
              <bias_mean>0.0000075</bias_mean>
              <bias_stddev>0.0000008</bias_stddev>
            </noise>
          </y>
          <z>
            <noise type="gaussian">
              <mean>0.0</mean>
              <stddev>2e-4</stddev>
              <bias_mean>0.0000075</bias_mean>
              <bias_stddev>0.0000008</bias_stddev>
            </noise>
          </z>
        </angular_velocity>
        <linear_acceleration>
          <x>
            <noise type="gaussian">
              <mean>0.0</mean>
              <stddev>1.7e-2</stddev>
              <bias_mean>0.1</bias_mean>
              <bias_stddev>0.001</bias_stddev>
            </noise>
          </x>
          <y>
            <noise type="gaussian">
              <mean>0.0</mean>
              <stddev>1.7e-2</stddev>
              <bias_mean>0.1</bias_mean>
              <bias_stddev>0.001</bias_stddev>
            </noise>
          </y>
          <z>
            <noise type="gaussian">
              <mean>0.0</mean>
              <stddev>1.7e-2</stddev>
              <bias_mean>0.1</bias_mean>
              <bias_stddev>0.001</bias_stddev>
            </noise>
          </z>
        </linear_acceleration>
      </imu>
      <plugin name="imu_plugin" filename="libgazebo_ros_imu_sensor.so">
        <ros>
          <namespace>imu</namespace>
          <remapping>~/out:=data</remapping>
        </ros>
        <initial_orientation_as_reference>false</initial_orientation_as_reference>
      </plugin>
    </sensor>
  </gazebo>

  <gazebo>
    <!-- Joint state publisher -->
    <plugin filename="libgazebo_ros2_control.so" name="gazebo_ros2_control">
      <parameters>$(find diff_drive_description)/config/diff_drive_controller.yaml</parameters>
    </plugin>
  </gazebo>

</robot>
